(dj_env) ka20381395@C02HF29UQ6L5 Feed_app % python manage.py createssuperuser
Unknown command: 'createssuperuser'. Did you mean createsuperuser?
Type 'manage.py help' for usage.
(dj_env) ka20381395@C02HF29UQ6L5 Feed_app % python manage.py createsuperuser 
Username (leave blank to use 'ka20381395'): Kalpana
Email address: kalpana123@gmail.com
Password: 
Password (again): 
This password is too short. It must contain at least 8 characters.
This password is too common.
This password is entirely numeric.
Bypass password validation and create user anyway? [y/N]: N
Password: 
Password (again): 
This password is too common.
This password is entirely numeric.
Bypass password validation and create user anyway? [y/N]: N
Password: 
Password (again): 
This password is entirely numeric.
Bypass password validation and create user anyway? [y/N]: y
Superuser created successfully.
(dj_env) ka20381395@C02HF29UQ6L5 Feed_app % clear

(dj_env) ka20381395@C02HF29UQ6L5 Feed_app % python manage.py makemigrations
Migrations for 'blog':
  blog/migrations/0001_initial.py
    + Create model Post
(dj_env) ka20381395@C02HF29UQ6L5 Feed_app % python manage.py sqlmigrate blog 0001
BEGIN;
--
-- Create model Post
--
CREATE TABLE "blog_post" ("id" integer NOT NULL PRIMARY KEY AUTOINCREMENT, "title" varchar(100) NOT NULL, "content" text NOT NULL, "date_posted" datetime NOT NULL, "author_id" integer NOT NULL REFERENCES "auth_user" ("id") DEFERRABLE INITIALLY DEFERRED);
CREATE INDEX "blog_post_author_id_dd7a8485" ON "blog_post" ("author_id");
COMMIT;
(dj_env) ka20381395@C02HF29UQ6L5 Feed_app % python manage.py migrate
Operations to perform:
  Apply all migrations: admin, auth, blog, contenttypes, sessions
Running migrations:
  Applying blog.0001_initial... OK
(dj_env) ka20381395@C02HF29UQ6L5 Feed_app % python manage.py shell
Python 3.12.4 (v3.12.4:8e8a4baf65, Jun  6 2024, 17:33:18) [Clang 13.0.0 (clang-1300.0.29.30)] on darwin
Type "help", "copyright", "credits" or "license" for more information.
(InteractiveConsole)
>>> from blog.models import Post
>>> from django.contrib.auth.models import User
>>> User.objects.all()
<QuerySet [<User: Kalpana>]>
>>> User.objects.first()
<User: Kalpana>
>>> User.objects.filter(username='Kalpana')
<QuerySet [<User: Kalpana>]>
>>> user = User.objects.filter(username='Kalpana')
>>> user
<QuerySet [<User: Kalpana>]>
>>> user.id
Traceback (most recent call last):
  File "<console>", line 1, in <module>
AttributeError: 'QuerySet' object has no attribute 'id'
>>> user = User.objects.filter(username='Kalpana').first()
>>> user
<User: Kalpana>
>>> user.id
1
>>> user.pk
1
>>> user = User.objects.get(id =1)
>>> user
<User: Kalpana>
>>> Post.object.all()
Traceback (most recent call last):
  File "<console>", line 1, in <module>
AttributeError: type object 'Post' has no attribute 'object'. Did you mean: 'objects'?
>>> Post.objects.all()
<QuerySet []>
>>> post_1 = Post(title="Learn the way you like",content="Be specilaized in a thing you love to do.",author="Kalpana")
Traceback (most recent call last):
  File "<console>", line 1, in <module>
  File "/Users/ka20381395/Desktop/Django_Corey/dj_env/lib/python3.12/site-packages/django/db/models/base.py", line 543, in __init__
    _setattr(self, field.name, rel_obj)
  File "/Users/ka20381395/Desktop/Django_Corey/dj_env/lib/python3.12/site-packages/django/db/models/fields/related_descriptors.py", line 287, in __set__
    raise ValueError(
ValueError: Cannot assign "'Kalpana'": "Post.author" must be a "User" instance.
>>> post_1 = Post(title="Learn the way you like",content="Be specilaized in a thing you love to do.",author=user)
>>> Post.objects.all()
<QuerySet []>
>>> post_1.save()
>>> Post.objects.all()
<QuerySet [<Post: Post object (1)>]>
>>> exit()
(dj_env) ka20381395@C02HF29UQ6L5 Feed_app % python manage.py shell
Python 3.12.4 (v3.12.4:8e8a4baf65, Jun  6 2024, 17:33:18) [Clang 13.0.0 (clang-1300.0.29.30)] on darwin
Type "help", "copyright", "credits" or "license" for more information.
(InteractiveConsole)
>>> from blog.models import Post
>>> from django.contrib.auth.models import User
>>> Post.objects.all()
<QuerySet [<Post: Learn the way you like>]>
>>> user = User.objects.filter(username='Kalpana').first()
>>> user
<User: Kalpana>
>>> post_2 = Post(title="Django",content="Django tutorial by corey schafer")
>>> post_2.save()
Traceback (most recent call last):
  File "/Users/ka20381395/Desktop/Django_Corey/dj_env/lib/python3.12/site-packages/django/db/backends/utils.py", line 105, in _execute
    return self.cursor.execute(sql, params)
           ^^^^^^^^^^^^^^^^^^^^^^^^^^^^^^^^
  File "/Users/ka20381395/Desktop/Django_Corey/dj_env/lib/python3.12/site-packages/django/db/backends/sqlite3/base.py", line 354, in execute
    return super().execute(query, params)
           ^^^^^^^^^^^^^^^^^^^^^^^^^^^^^^
sqlite3.IntegrityError: NOT NULL constraint failed: blog_post.author_id

The above exception was the direct cause of the following exception:

Traceback (most recent call last):
  File "<console>", line 1, in <module>
  File "/Users/ka20381395/Desktop/Django_Corey/dj_env/lib/python3.12/site-packages/django/db/models/base.py", line 891, in save
    self.save_base(
  File "/Users/ka20381395/Desktop/Django_Corey/dj_env/lib/python3.12/site-packages/django/db/models/base.py", line 997, in save_base
    updated = self._save_table(
              ^^^^^^^^^^^^^^^^^
  File "/Users/ka20381395/Desktop/Django_Corey/dj_env/lib/python3.12/site-packages/django/db/models/base.py", line 1160, in _save_table
    results = self._do_insert(
              ^^^^^^^^^^^^^^^^
  File "/Users/ka20381395/Desktop/Django_Corey/dj_env/lib/python3.12/site-packages/django/db/models/base.py", line 1201, in _do_insert
    return manager._insert(
           ^^^^^^^^^^^^^^^^
  File "/Users/ka20381395/Desktop/Django_Corey/dj_env/lib/python3.12/site-packages/django/db/models/manager.py", line 87, in manager_method
    return getattr(self.get_queryset(), name)(*args, **kwargs)
           ^^^^^^^^^^^^^^^^^^^^^^^^^^^^^^^^^^^^^^^^^^^^^^^^^^^
  File "/Users/ka20381395/Desktop/Django_Corey/dj_env/lib/python3.12/site-packages/django/db/models/query.py", line 1847, in _insert
    return query.get_compiler(using=using).execute_sql(returning_fields)
           ^^^^^^^^^^^^^^^^^^^^^^^^^^^^^^^^^^^^^^^^^^^^^^^^^^^^^^^^^^^^^
  File "/Users/ka20381395/Desktop/Django_Corey/dj_env/lib/python3.12/site-packages/django/db/models/sql/compiler.py", line 1836, in execute_sql
    cursor.execute(sql, params)
  File "/Users/ka20381395/Desktop/Django_Corey/dj_env/lib/python3.12/site-packages/django/db/backends/utils.py", line 122, in execute
    return super().execute(sql, params)
           ^^^^^^^^^^^^^^^^^^^^^^^^^^^^
  File "/Users/ka20381395/Desktop/Django_Corey/dj_env/lib/python3.12/site-packages/django/db/backends/utils.py", line 79, in execute
    return self._execute_with_wrappers(
           ^^^^^^^^^^^^^^^^^^^^^^^^^^^^
  File "/Users/ka20381395/Desktop/Django_Corey/dj_env/lib/python3.12/site-packages/django/db/backends/utils.py", line 92, in _execute_with_wrappers
    return executor(sql, params, many, context)
           ^^^^^^^^^^^^^^^^^^^^^^^^^^^^^^^^^^^^
  File "/Users/ka20381395/Desktop/Django_Corey/dj_env/lib/python3.12/site-packages/django/db/backends/utils.py", line 100, in _execute
    with self.db.wrap_database_errors:
  File "/Users/ka20381395/Desktop/Django_Corey/dj_env/lib/python3.12/site-packages/django/db/utils.py", line 91, in __exit__
    raise dj_exc_value.with_traceback(traceback) from exc_value
  File "/Users/ka20381395/Desktop/Django_Corey/dj_env/lib/python3.12/site-packages/django/db/backends/utils.py", line 105, in _execute
    return self.cursor.execute(sql, params)
           ^^^^^^^^^^^^^^^^^^^^^^^^^^^^^^^^
  File "/Users/ka20381395/Desktop/Django_Corey/dj_env/lib/python3.12/site-packages/django/db/backends/sqlite3/base.py", line 354, in execute
    return super().execute(query, params)
           ^^^^^^^^^^^^^^^^^^^^^^^^^^^^^^
django.db.utils.IntegrityError: NOT NULL constraint failed: blog_post.author_id
>>> post_2 = Post(title="Django",content="Django tutorial by corey schafer",author_id=user_id)
Traceback (most recent call last):
  File "<console>", line 1, in <module>
NameError: name 'user_id' is not defined
>>> post_2 = Post(title="Django",content="Django tutorial by corey schafer",author_id=user.id)
>>> post_2.save()                                                               >>> Post.objects.all()
<QuerySet [<Post: Learn the way you like>, <Post: Django>]>
>>> post=Post.objects.first()
>>> post.content
'Be specilaized in a thing you love to do.'
>>> post.date_posted
datetime.datetime(2024, 11, 6, 11, 7, 19, 674776, tzinfo=datetime.timezone.utc)
>>> post.author
<User: Kalpana>
>>> post.author.email
'kalpana123@gmail.com'
>>> post.objects.all()
Traceback (most recent call last):
  File "<console>", line 1, in <module>
  File "/Users/ka20381395/Desktop/Django_Corey/dj_env/lib/python3.12/site-packages/django/db/models/manager.py", line 186, in __get__
    raise AttributeError(
AttributeError: Manager isn't accessible via Post instances
>>> Post.objects.all()
<QuerySet [<Post: Learn the way you like>, <Post: Django>]>
>>> user
<User: Kalpana>
>>> user.Post_set
Traceback (most recent call last):
  File "<console>", line 1, in <module>
AttributeError: 'User' object has no attribute 'Post_set'. Did you mean: 'post_set'?
>>> user.Post_set.all()
Traceback (most recent call last):
  File "<console>", line 1, in <module>
AttributeError: 'User' object has no attribute 'Post_set'. Did you mean: 'post_set'?
>>> user.post_set.all()
<QuerySet [<Post: Learn the way you like>, <Post: Django>]>
>>> user.post_set
<django.db.models.fields.related_descriptors.create_reverse_many_to_one_manager.<locals>.RelatedManager object at 0x1012e8ef0>
>>> user.post_set.all()
<QuerySet [<Post: Learn the way you like>, <Post: Django>]>
>>> user.post_set.create(title="Self-Confidence",content="Learn to accept the shame")
<Post: Self-Confidence>
>>> Post.objects.all()
<QuerySet [<Post: Learn the way you like>, <Post: Django>, <Post: Self-Confidence>]>
>>> exit()
(dj_env) ka20381395@C02HF29UQ6L5 Feed_app % python manage.py runserver
Watching for file changes with StatReloader
Performing system checks...

System check identified no issues (0 silenced).
Error: That port is already in use.
(dj_env) ka20381395@C02HF29UQ6L5 Feed_app % 
